<mujoco model="unnamed_model">
  <default>
    <default class="/"/>
  </default>
  <worldbody>
    <geom name="//unnamed_geom_0" class="/" type="plane" size="100 100 0.10000000000000001" pos="0 0 -10"/>
    <body name="body0" pos="0 0 0">
      <joint name="//unnamed_joint_0" class="/" type="free"/>
      <geom name="//unnamed_geom_1" class="/" type="sphere" size="0.27277871723735969 0.27277871723735969 0.27277871723735969"/>
      <body name="body1" pos="0 0 -0.9941050248104879">
        <geom name="//unnamed_geom_2" class="/" type="sphere" size="0.72132630757312821 0.72132630757312821 0.72132630757312821"/>
        <joint name="//unnamed_joint_1" class="/" type="hinge" axis="0 0 -1"/>
        <body name="body2" pos="1.5734808438322592 0 0">
          <geom name="//unnamed_geom_3" class="/" type="sphere" size="0.85215453625913096 0.85215453625913096 0.85215453625913096"/>
          <joint name="//unnamed_joint_2" class="/" type="hinge" axis="1 0 0"/>
          <body name="body4" pos="0 -1.1019040628729289 0">
            <geom name="//unnamed_geom_4" class="/" type="sphere" size="0.2497495266137979 0.2497495266137979 0.2497495266137979"/>
            <joint name="//unnamed_joint_3" class="/" type="ball" axis="0 -1 0"/>
            <body name="body6" pos="-0.82573328149127834 0 0">
              <geom name="//unnamed_geom_5" class="/" type="sphere" size="0.57598375487748044 0.57598375487748044 0.57598375487748044"/>
              <joint name="//unnamed_joint_4" class="/" type="ball" axis="-1 0 0"/>
              <body name="body9" pos="0 0 1.4039954636808969">
                <geom name="//unnamed_geom_6" class="/" type="sphere" size="0.82801170880341657 0.82801170880341657 0.82801170880341657"/>
                <joint name="//unnamed_joint_5" class="/" type="hinge" axis="0 0 1"/>
              </body>
            </body>
            <body name="body7" pos="0 0 0.95185686615205745">
              <geom name="//unnamed_geom_7" class="/" type="sphere" size="0.70210733953825955 0.70210733953825955 0.70210733953825955"/>
              <joint name="//unnamed_joint_6" class="/" type="ball" axis="0 0 1"/>
            </body>
          </body>
          <body name="body10" pos="0 1.2332698389411669 0">
            <geom name="//unnamed_geom_8" class="/" type="sphere" size="0.38111530268203597 0.38111530268203597 0.38111530268203597"/>
            <joint name="//unnamed_joint_7" class="/" type="hinge" axis="0 1 0"/>
          </body>
        </body>
        <body name="body8" pos="0 -1.4728165371561843 0">
          <geom name="//unnamed_geom_9" class="/" type="sphere" size="0.75149022958305611 0.75149022958305611 0.75149022958305611"/>
          <joint name="//unnamed_joint_8" class="/" type="hinge" axis="0 -1 0"/>
        </body>
        <body name="body11" pos="0 0 -1.6560063996771071">
          <geom name="//unnamed_geom_10" class="/" type="sphere" size="0.93468009210397884 0.93468009210397884 0.93468009210397884"/>
          <joint name="//unnamed_joint_9" class="/" type="ball" axis="0 0 -1"/>
        </body>
      </body>
      <body name="body3" pos="-0.95102091983029047 0 0">
        <geom name="//unnamed_geom_11" class="/" type="sphere" size="0.67824220259293078 0.67824220259293078 0.67824220259293078"/>
        <joint name="//unnamed_joint_10" class="/" type="ball" axis="-1 0 0"/>
        <body name="body5" pos="0 1.5676967774560975 0">
          <geom name="//unnamed_geom_12" class="/" type="sphere" size="0.88945457486316659 0.88945457486316659 0.88945457486316659"/>
          <joint name="//unnamed_joint_11" class="/" type="hinge" axis="0 1 0"/>
        </body>
      </body>
    </body>
  </worldbody>
  <actuator>
    <motor name="//unnamed_actuator_0" class="/" ctrllimited="true" ctrlrange="-1 1" joint="//unnamed_joint_0"/>
    <motor name="//unnamed_actuator_1" class="/" ctrllimited="true" ctrlrange="-1 1" joint="//unnamed_joint_1"/>
    <motor name="//unnamed_actuator_2" class="/" ctrllimited="true" ctrlrange="-1 1" joint="//unnamed_joint_2"/>
    <motor name="//unnamed_actuator_3" class="/" ctrllimited="true" ctrlrange="-1 1" joint="//unnamed_joint_3"/>
    <motor name="//unnamed_actuator_4" class="/" ctrllimited="true" ctrlrange="-1 1" joint="//unnamed_joint_4"/>
    <motor name="//unnamed_actuator_5" class="/" ctrllimited="true" ctrlrange="-1 1" joint="//unnamed_joint_5"/>
    <motor name="//unnamed_actuator_6" class="/" ctrllimited="true" ctrlrange="-1 1" joint="//unnamed_joint_6"/>
    <motor name="//unnamed_actuator_7" class="/" ctrllimited="true" ctrlrange="-1 1" joint="//unnamed_joint_7"/>
    <motor name="//unnamed_actuator_8" class="/" ctrllimited="true" ctrlrange="-1 1" joint="//unnamed_joint_8"/>
    <motor name="//unnamed_actuator_9" class="/" ctrllimited="true" ctrlrange="-1 1" joint="//unnamed_joint_9"/>
    <motor name="//unnamed_actuator_10" class="/" ctrllimited="true" ctrlrange="-1 1" joint="//unnamed_joint_10"/>
    <motor name="//unnamed_actuator_11" class="/" ctrllimited="true" ctrlrange="-1 1" joint="//unnamed_joint_11"/>
  </actuator>
</mujoco>
